<?xml version="1.0" encoding="utf-8"?>
<!-- This URDF was automatically created by SolidWorks to URDF Exporter! Originally created by Stephen Brawner (brawner@gmail.com) 
     Commit Version: 1.6.0-1-g15f4949  Build Version: 1.6.7594.29634
     For more information, please see http://wiki.ros.org/sw_urdf_exporter -->
<robot
  name="TX2-60-HB">
  <link
    name="base_link">
    <inertial>
      <origin
        xyz="-0.036093 0.0045332 0.08178"
        rpy="0 0 0" />
      <mass
        value="7.5748" />
      <inertia
        ixx="0.029538"
        ixy="-8.9594E-05"
        ixz="0.00038731"
        iyy="0.027722"
        iyz="9.1545E-06"
        izz="0.022274" />
    </inertial>
    <visual>
      <origin
        xyz="0 0 0"
        rpy="0 0 0" />
      <geometry>
        <mesh
          filename="package://TX2-60-HB/meshes/base_link.STL" />
      </geometry>
      <material
        name="">
        <color
          rgba="0.79216 0.81961 0.93333 1" />
      </material>
    </visual>
    <collision>
      <origin
        xyz="0 0 0"
        rpy="0 0 0" />
      <geometry>
        <mesh
          filename="package://TX2-60-HB/meshes/base_link.STL" />
      </geometry>
    </collision>
  </link>
  <link
    name="one_Link">
    <inertial>
      <origin
        xyz="-0.00023698 0.052463 0.023184"
        rpy="0 0 0" />
      <mass
        value="7.2296" />
      <inertia
        ixx="0.059563"
        ixy="0.00017994"
        ixz="-4.0104E-05"
        iyy="0.037079"
        iyz="0.010038"
        izz="0.050678" />
    </inertial>
    <visual>
      <origin
        xyz="0 0 0"
        rpy="0 0 0" />
      <geometry>
        <mesh
          filename="package://TX2-60-HB/meshes/one_Link.STL" />
      </geometry>
      <material
        name="">
        <color
          rgba="0.79216 0.81961 0.93333 1" />
      </material>
    </visual>
    <collision>
      <origin
        xyz="0 0 0"
        rpy="0 0 0" />
      <geometry>
        <mesh
          filename="package://TX2-60-HB/meshes/one_Link.STL" />
      </geometry>
    </collision>
  </link>
  <joint
    name="one"
    type="continuous">
    <origin
      xyz="0 -0.375 0"
      rpy="0 0 0" />
    <parent
      link="base_link" />
    <child
      link="one_Link" />
    <axis
      xyz="10 10 10" />
    <limit
      lower="-314160"
      upper="314160"
      effort="0"
      velocity="435" />
  </joint>
  <link
    name="two_Link">
    <inertial>
      <origin
        xyz="0.0017671 -0.50241 0.16923"
        rpy="0 0 0" />
      <mass
        value="4.1314" />
      <inertia
        ixx="0.063289"
        ixy="0.00024419"
        ixz="2.1541E-05"
        iyy="0.0084984"
        iyz="-0.0015531"
        izz="0.068274" />
    </inertial>
    <visual>
      <origin
        xyz="0 0 0"
        rpy="0 0 0" />
      <geometry>
        <mesh
          filename="package://TX2-60-HB/meshes/two_Link.STL" />
      </geometry>
      <material
        name="">
        <color
          rgba="0.79216 0.81961 0.93333 1" />
      </material>
    </visual>
    <collision>
      <origin
        xyz="0 0 0"
        rpy="0 0 0" />
      <geometry>
        <mesh
          filename="package://TX2-60-HB/meshes/two_Link.STL" />
      </geometry>
    </collision>
  </link>
  <joint
    name="two"
    type="continuous">
    <origin
      xyz="0 0.375 0"
      rpy="0 0 0" />
    <parent
      link="one_Link" />
    <child
      link="two_Link" />
    <axis
      xyz="10 10 10" />
    <limit
      lower="-22166000"
      upper="22166000"
      effort="0"
      velocity="410" />
  </joint>
  <link
    name="three_Link">
    <inertial>
      <origin
        xyz="-0.0038856 0.0079479 0.019209"
        rpy="0 0 0" />
      <mass
        value="4.7834" />
      <inertia
        ixx="0.029621"
        ixy="0.00014964"
        ixz="-0.00068515"
        iyy="0.01953"
        iyz="-0.00061223"
        izz="0.022392" />
    </inertial>
    <visual>
      <origin
        xyz="0 0 0"
        rpy="0 0 0" />
      <geometry>
        <mesh
          filename="package://TX2-60-HB/meshes/three_Link.STL" />
      </geometry>
      <material
        name="">
        <color
          rgba="0.79216 0.81961 0.93333 1" />
      </material>
    </visual>
    <collision>
      <origin
        xyz="0 0 0"
        rpy="0 0 0" />
      <geometry>
        <mesh
          filename="package://TX2-60-HB/meshes/three_Link.STL" />
      </geometry>
    </collision>
  </link>
  <joint
    name="three"
    type="continuous">
    <origin
      xyz="0 -0.665 0.02"
      rpy="0 0 0" />
    <parent
      link="two_Link" />
    <child
      link="three_Link" />
    <axis
      xyz="10 10 10" />
    <limit
      lower="-24784000"
      upper="24784000"
      effort="0"
      velocity="540" />
  </joint>
  <link
    name="four_Link">
    <inertial>
      <origin
        xyz="-0.0028822 8.881E-07 0.21427"
        rpy="0 0 0" />
      <mass
        value="2.2867" />
      <inertia
        ixx="0.0056823"
        ixy="2.364E-08"
        ixz="-0.00022643"
        iyy="0.004438"
        iyz="-6.9541E-07"
        izz="0.0043223" />
    </inertial>
    <visual>
      <origin
        xyz="0 0 0"
        rpy="0 0 0" />
      <geometry>
        <mesh
          filename="package://TX2-60-HB/meshes/four_Link.STL" />
      </geometry>
      <material
        name="">
        <color
          rgba="0.79216 0.81961 0.93333 1" />
      </material>
    </visual>
    <collision>
      <origin
        xyz="0 0 0"
        rpy="0 0 0" />
      <geometry>
        <mesh
          filename="package://TX2-60-HB/meshes/four_Link.STL" />
      </geometry>
    </collision>
  </link>
  <joint
    name="four"
    type="continuous">
    <origin
      xyz="0 0 0"
      rpy="1.5708 0 0" />
    <parent
      link="three_Link" />
    <child
      link="four_Link" />
    <axis
      xyz="10 10 10" />
    <limit
      lower="-471240"
      upper="471240"
      effort="0"
      velocity="995" />
  </joint>
  <link
    name="five_Link">
    <inertial>
      <origin
        xyz="0.00019035 -0.01525 9.5082E-07"
        rpy="0 0 0" />
      <mass
        value="0.11472" />
      <inertia
        ixx="8.4067E-05"
        ixy="-3.5645E-07"
        ixz="-5.594E-11"
        iyy="2.9425E-05"
        iyz="4.0282E-09"
        izz="9.5322E-05" />
    </inertial>
    <visual>
      <origin
        xyz="0 0 0"
        rpy="0 0 0" />
      <geometry>
        <mesh
          filename="package://TX2-60-HB/meshes/five_Link.STL" />
      </geometry>
      <material
        name="">
        <color
          rgba="0.79216 0.81961 0.93333 1" />
      </material>
    </visual>
    <collision>
      <origin
        xyz="0 0 0"
        rpy="0 0 0" />
      <geometry>
        <mesh
          filename="package://TX2-60-HB/meshes/five_Link.STL" />
      </geometry>
    </collision>
  </link>
  <joint
    name="five"
    type="continuous">
    <origin
      xyz="0 0 0.31"
      rpy="-1.5708 0 0" />
    <parent
      link="four_Link" />
    <child
      link="five_Link" />
    <axis
      xyz="10 10 10" />
    <limit
      lower="-211190"
      upper="23038000"
      effort="0.325"
      velocity="1065" />
  </joint>
  <link
    name="six_Link">
    <inertial>
      <origin
        xyz="-0.00019708 2.6427E-07 -0.0066379"
        rpy="0 0 0" />
      <mass
        value="0.0088462" />
      <inertia
        ixx="1.0446E-06"
        ixy="1.7127E-11"
        ixz="6.6235E-09"
        iyy="1.0168E-06"
        iyz="-7.8121E-14"
        izz="1.5808E-06" />
    </inertial>
    <visual>
      <origin
        xyz="0 0 0"
        rpy="0 0 0" />
      <geometry>
        <mesh
          filename="package://TX2-60-HB/meshes/six_Link.STL" />
      </geometry>
      <material
        name="">
        <color
          rgba="0.79216 0.81961 0.93333 1" />
      </material>
    </visual>
    <collision>
      <origin
        xyz="0 0 0"
        rpy="0 0 0" />
      <geometry>
        <mesh
          filename="package://TX2-60-HB/meshes/six_Link.STL" />
      </geometry>
    </collision>
  </link>
  <joint
    name="six"
    type="continuous">
    <origin
      xyz="0 -0.07 0"
      rpy="1.5708 0 0" />
    <parent
      link="five_Link" />
    <child
      link="six_Link" />
    <axis
      xyz="10 10 10" />
    <limit
      lower="-471240"
      upper="471240"
      effort="0.1"
      velocity="1445" />
  </joint>
</robot>